"""
Verify that database error handling in query.py works correctly.

This script tests that:
1. Database operations are wrapped in try/except
2. Errors are logged but don't break streaming
3. Streaming continues even if database save fails
"""

import sys
import re
from pathlib import Path


def verify_error_handling():
    """Verify error handling implementation in query.py."""

    print("=" * 80)
    print("DATABASE ERROR HANDLING VERIFICATION")
    print("=" * 80)
    print()

    query_file = Path("backend/api/query.py")

    if not query_file.exists():
        print("‚ùå FAILED: query.py not found")
        return False

    content = query_file.read_text()

    # Test 1: Check for try-except blocks around database operations
    print("Test 1: Verify try-except blocks around database operations")
    print("-" * 80)

    # Check for user message saving error handling
    user_message_pattern = r'conversation_service\.save_message_with_sources\([^)]+role="user"[^)]*\).*?except Exception as e:'
    user_message_matches = re.findall(user_message_pattern, content, re.DOTALL)

    if len(user_message_matches) >= 2:  # Should be in both stream functions
        print("‚úÖ User message saving has try-except blocks")
        print(f"   Found {len(user_message_matches)} instances")
    else:
        print(
            f"‚ùå User message saving missing try-except blocks (found {len(user_message_matches)}, expected 2)"
        )
        return False

    # Check for assistant message saving error handling
    assistant_message_pattern = r'conversation_service\.save_message_with_sources\([^)]+role="assistant"[^)]*\).*?except Exception as e:'
    assistant_message_matches = re.findall(
        assistant_message_pattern, content, re.DOTALL
    )

    if len(assistant_message_matches) >= 2:  # Should be in both stream functions
        print("‚úÖ Assistant message saving has try-except blocks")
        print(f"   Found {len(assistant_message_matches)} instances")
    else:
        print(
            f"‚ùå Assistant message saving missing try-except blocks (found {len(assistant_message_matches)}, expected 2)"
        )
        return False

    print()

    # Test 2: Check for error logging
    print("Test 2: Verify error logging")
    print("-" * 80)

    # Check for logger.error calls with exc_info=True
    error_log_pattern = r"logger\.error\([^)]*Failed to save.*exc_info=True\)"
    error_log_matches = re.findall(error_log_pattern, content)

    if len(error_log_matches) >= 4:  # 2 for user messages, 2 for assistant messages
        print("‚úÖ Errors are logged with exc_info=True")
        print(f"   Found {len(error_log_matches)} error logging statements")
    else:
        print(
            f"‚ùå Missing error logging (found {len(error_log_matches)}, expected at least 4)"
        )
        return False

    print()

    # Test 3: Check for continue comments
    print("Test 3: Verify streaming continues after database failures")
    print("-" * 80)

    # Check for comments indicating continuation
    continue_pattern = r"# Continue.*even if database.*fails"
    continue_matches = re.findall(continue_pattern, content, re.IGNORECASE)

    if len(continue_matches) >= 4:
        print("‚úÖ Code explicitly continues streaming after database failures")
        print(f"   Found {len(continue_matches)} continuation comments")
    else:
        print(f"‚ö†Ô∏è  Found {len(continue_matches)} continuation comments (expected 4)")
        print("   This is acceptable as long as the logic is correct")

    print()

    # Test 4: Verify no re-raise of database exceptions
    print("Test 4: Verify database exceptions are not re-raised")
    print("-" * 80)

    # Check that database exceptions are caught and not re-raised
    # Look for patterns where we catch but don't raise
    reraise_pattern = r"except Exception as e:.*?raise"

    # Get all exception blocks
    exception_blocks = re.finditer(
        r"try:.*?except Exception as e:(.*?)(?=\n(?:    )?(?:try|except|async def|def|\Z))",
        content,
        re.DOTALL,
    )

    database_exception_blocks = []
    for match in exception_blocks:
        block = match.group(0)
        if "conversation_service" in block or "save_message" in block:
            database_exception_blocks.append(block)

    reraise_found = False
    for block in database_exception_blocks:
        if re.search(r"raise", block.split("except Exception as e:")[1]):
            reraise_found = True
            print(f"‚ùå Database exception is re-raised, which would break streaming")
            return False

    if not reraise_found:
        print("‚úÖ Database exceptions are caught and not re-raised")
        print("   Streaming will continue even if database operations fail")

    print()

    # Test 5: Check for proper error context
    print("Test 5: Verify error messages provide context")
    print("-" * 80)

    # Check that error messages are descriptive
    error_messages = re.findall(r'logger\.error\(f?"([^"]+)"', content)

    database_error_messages = [
        msg
        for msg in error_messages
        if "save" in msg.lower() or "database" in msg.lower()
    ]

    if len(database_error_messages) >= 4:
        print("‚úÖ Error messages provide context")
        for msg in database_error_messages[:4]:
            print(f"   - {msg}")
    else:
        print(f"‚ö†Ô∏è  Found {len(database_error_messages)} contextual error messages")

    print()

    # Summary
    print("=" * 80)
    print("VERIFICATION SUMMARY")
    print("=" * 80)
    print()
    print("‚úÖ All database operations are wrapped in try-except blocks")
    print("‚úÖ Errors are logged with full stack traces (exc_info=True)")
    print("‚úÖ Streaming continues even if database save fails")
    print("‚úÖ Database exceptions do not break the streaming response")
    print()
    print("üéâ DATABASE ERROR HANDLING VERIFICATION PASSED")
    print()

    return True


if __name__ == "__main__":
    try:
        success = verify_error_handling()
        sys.exit(0 if success else 1)
    except Exception as e:
        print(f"\n‚ùå Verification failed with error: {e}")
        import traceback

        traceback.print_exc()
        sys.exit(1)
